2025-07-29 17:52:43,138 - httpx - INFO - HTTP Request: POST https://api.telegram.org/bot6955797889:AAF03K6prjPeG1MvTlKva96zhoj_NeICBAU/getUpdates "HTTP/1.1 200 OK"
2025-07-29 17:52:43,147 - root - INFO - New user X91ja+01)$am (396380942) added to the database.
2025-07-29 17:52:48,457 - telegram.ext.Application - ERROR - No error handlers are registered, logging exception.
Traceback (most recent call last):
  File "d:\Projects\AI_TelegramBot\venv\Lib\site-packages\httpx\_transports\default.py", line 101, in map_httpcore_exceptions
    yield
  File "d:\Projects\AI_TelegramBot\venv\Lib\site-packages\httpx\_transports\default.py", line 394, in handle_async_request
    resp = await self._pool.handle_async_request(req)
           ^^^^^^^^^^^^^^^^^^^^^^^^^^^^^^^^^^^^^^^^^^
  File "d:\Projects\AI_TelegramBot\venv\Lib\site-packages\httpcore\_async\connection_pool.py", line 256, in handle_async_request
    raise exc from None
  File "d:\Projects\AI_TelegramBot\venv\Lib\site-packages\httpcore\_async\connection_pool.py", line 236, in handle_async_request
    response = await connection.handle_async_request(
               ^^^^^^^^^^^^^^^^^^^^^^^^^^^^^^^^^^^^^^
        pool_request.request
        ^^^^^^^^^^^^^^^^^^^^
    )
    ^
  File "d:\Projects\AI_TelegramBot\venv\Lib\site-packages\httpcore\_async\http_proxy.py", line 316, in handle_async_request
    stream = await stream.start_tls(**kwargs)
             ^^^^^^^^^^^^^^^^^^^^^^^^^^^^^^^^
  File "d:\Projects\AI_TelegramBot\venv\Lib\site-packages\httpcore\_async\http11.py", line 376, in start_tls
    return await self._stream.start_tls(ssl_context, server_hostname, timeout)
           ^^^^^^^^^^^^^^^^^^^^^^^^^^^^^^^^^^^^^^^^^^^^^^^^^^^^^^^^^^^^^^^^^^^
  File "d:\Projects\AI_TelegramBot\venv\Lib\site-packages\httpcore\_backends\anyio.py", line 67, in start_tls
    with map_exceptions(exc_map):
         ~~~~~~~~~~~~~~^^^^^^^^^
  File "C:\Program Files\WindowsApps\PythonSoftwareFoundation.Python.3.13_3.13.1520.0_x64__qbz5n2kfra8p0\Lib\contextlib.py", line 162, in __exit__
    self.gen.throw(value)
    ~~~~~~~~~~~~~~^^^^^^^
  File "d:\Projects\AI_TelegramBot\venv\Lib\site-packages\httpcore\_exceptions.py", line 14, in map_exceptions
    raise to_exc(exc) from exc
httpcore.ConnectTimeout

The above exception was the direct cause of the following exception:

Traceback (most recent call last):
  File "d:\Projects\AI_TelegramBot\venv\Lib\site-packages\telegram\request\_httpxrequest.py", line 273, in do_request
    res = await self._client.request(
          ^^^^^^^^^^^^^^^^^^^^^^^^^^^
    ...<6 lines>...
    )
    ^
  File "d:\Projects\AI_TelegramBot\venv\Lib\site-packages\httpx\_client.py", line 1540, in request
    return await self.send(request, auth=auth, follow_redirects=follow_redirects)
           ^^^^^^^^^^^^^^^^^^^^^^^^^^^^^^^^^^^^^^^^^^^^^^^^^^^^^^^^^^^^^^^^^^^^^^
  File "d:\Projects\AI_TelegramBot\venv\Lib\site-packages\httpx\_client.py", line 1629, in send
    response = await self._send_handling_auth(
               ^^^^^^^^^^^^^^^^^^^^^^^^^^^^^^^
    ...<4 lines>...
    )
    ^
  File "d:\Projects\AI_TelegramBot\venv\Lib\site-packages\httpx\_client.py", line 1657, in _send_handling_auth
    response = await self._send_handling_redirects(
               ^^^^^^^^^^^^^^^^^^^^^^^^^^^^^^^^^^^^
    ...<3 lines>...
    )
    ^
  File "d:\Projects\AI_TelegramBot\venv\Lib\site-packages\httpx\_client.py", line 1694, in _send_handling_redirects
    response = await self._send_single_request(request)
               ^^^^^^^^^^^^^^^^^^^^^^^^^^^^^^^^^^^^^^^^
  File "d:\Projects\AI_TelegramBot\venv\Lib\site-packages\httpx\_client.py", line 1730, in _send_single_request
    response = await transport.handle_async_request(request)
               ^^^^^^^^^^^^^^^^^^^^^^^^^^^^^^^^^^^^^^^^^^^^^
  File "d:\Projects\AI_TelegramBot\venv\Lib\site-packages\httpx\_transports\default.py", line 393, in handle_async_request
    with map_httpcore_exceptions():
         ~~~~~~~~~~~~~~~~~~~~~~~^^
  File "C:\Program Files\WindowsApps\PythonSoftwareFoundation.Python.3.13_3.13.1520.0_x64__qbz5n2kfra8p0\Lib\contextlib.py", line 162, in __exit__
    self.gen.throw(value)
    ~~~~~~~~~~~~~~^^^^^^^
  File "d:\Projects\AI_TelegramBot\venv\Lib\site-packages\httpx\_transports\default.py", line 118, in map_httpcore_exceptions
    raise mapped_exc(message) from exc
httpx.ConnectTimeout

The above exception was the direct cause of the following exception:

Traceback (most recent call last):
  File "d:\Projects\AI_TelegramBot\venv\Lib\site-packages\telegram\ext\_application.py", line 1311, in process_update
    await coroutine
  File "d:\Projects\AI_TelegramBot\venv\Lib\site-packages\telegram\ext\_handlers\conversationhandler.py", line 842, in handle_update
    new_state: object = await handler.handle_update(
                        ^^^^^^^^^^^^^^^^^^^^^^^^^^^^
        update, application, handler_check_result, context
        ^^^^^^^^^^^^^^^^^^^^^^^^^^^^^^^^^^^^^^^^^^^^^^^^^^
    )
    ^
  File "d:\Projects\AI_TelegramBot\venv\Lib\site-packages\telegram\ext\_handlers\basehandler.py", line 158, in handle_update
    return await self.callback(update, context)
           ^^^^^^^^^^^^^^^^^^^^^^^^^^^^^^^^^^^^
  File "D:\Projects\AI_TelegramBot\src\handlers\handlers.py", line 29, in start
    await update.message.reply_text(
    ...<2 lines>...
    )
  File "d:\Projects\AI_TelegramBot\venv\Lib\site-packages\telegram\_message.py", line 1910, in reply_text
    return await self.get_bot().send_message(
           ^^^^^^^^^^^^^^^^^^^^^^^^^^^^^^^^^^
    ...<19 lines>...
    )
    ^
  File "d:\Projects\AI_TelegramBot\venv\Lib\site-packages\telegram\ext\_extbot.py", line 3055, in send_message
    return await super().send_message(
           ^^^^^^^^^^^^^^^^^^^^^^^^^^^
    ...<21 lines>...
    )
    ^
  File "d:\Projects\AI_TelegramBot\venv\Lib\site-packages\telegram\_bot.py", line 1100, in send_message
    return await self._send_message(
           ^^^^^^^^^^^^^^^^^^^^^^^^^
    ...<19 lines>...
    )
    ^
  File "d:\Projects\AI_TelegramBot\venv\Lib\site-packages\telegram\ext\_extbot.py", line 630, in _send_message
    result = await super()._send_message(
             ^^^^^^^^^^^^^^^^^^^^^^^^^^^^
    ...<21 lines>...
    )
    ^
  File "d:\Projects\AI_TelegramBot\venv\Lib\site-packages\telegram\_bot.py", line 810, in _send_message
    result = await self._post(
             ^^^^^^^^^^^^^^^^^
    ...<7 lines>...
    )
    ^
  File "d:\Projects\AI_TelegramBot\venv\Lib\site-packages\telegram\_bot.py", line 698, in _post
    return await self._do_post(
           ^^^^^^^^^^^^^^^^^^^^
    ...<6 lines>...
    )
    ^
  File "d:\Projects\AI_TelegramBot\venv\Lib\site-packages\telegram\ext\_extbot.py", line 370, in _do_post
    return await super()._do_post(
           ^^^^^^^^^^^^^^^^^^^^^^^
    ...<6 lines>...
    )
    ^
  File "d:\Projects\AI_TelegramBot\venv\Lib\site-packages\telegram\_bot.py", line 727, in _do_post
    result = await request.post(
             ^^^^^^^^^^^^^^^^^^^
    ...<6 lines>...
    )
    ^
  File "d:\Projects\AI_TelegramBot\venv\Lib\site-packages\telegram\request\_baserequest.py", line 197, in post
    result = await self._request_wrapper(
             ^^^^^^^^^^^^^^^^^^^^^^^^^^^^
    ...<7 lines>...
    )
    ^
  File "d:\Projects\AI_TelegramBot\venv\Lib\site-packages\telegram\request\_baserequest.py", line 304, in _request_wrapper
    code, payload = await self.do_request(
                    ^^^^^^^^^^^^^^^^^^^^^^
    ...<7 lines>...
    )
    ^
  File "d:\Projects\AI_TelegramBot\venv\Lib\site-packages\telegram\request\_httpxrequest.py", line 290, in do_request
    raise TimedOut from err
telegram.error.TimedOut: Timed out
2025-07-29 17:52:53,243 - httpx - INFO - HTTP Request: POST https://api.telegram.org/bot6955797889:AAF03K6prjPeG1MvTlKva96zhoj_NeICBAU/getUpdates "HTTP/1.1 200 OK"